Question 1
Complete
Marked out of 1.00
Flag question
Question text
What is the result of compiling and executing the below code with the mentioned arguments ?

java TestInvocation Welcome Year 2009

public class TestInvocation

{

    public static void main(String... args)

    {

        String arg1 = args[1];

   String arg2 = args[2];

        String arg3 = args[3];

    }

}



Question 1Answer

a.
Compilation succeeds 


b.
None of the mentioned. 


c.
Compilation fails 


d.
Throws exception at runtime

Question 2
Complete
Marked out of 1.00
Flag question
Question text
Given the following,

public class MyProgram {

public static void throwit() {

throw new RuntimeException();

}

public static void main(String args[]){

try {

System.out.println("Hello world ");

throwit();

System.out.println("Done with try block ");

}

finally {

System.out.println("Finally executing ");

}

}

}

Which answer most closely indicates the behavior of the program?



Question 2Answer

a.
The program will not compile. 


b.
The program will print Hello world, then will print that a RuntimeException has occurred, then will print Done with try block, and then will print Finally executing. 


c.
The program will print Hello world, then will print Finally executing, then will print that a RuntimeException has occurred.


d.
The program will print Hello world, then will print that a RuntimeException has occurred, and then will print Finally executing. 

Question 3
Complete
Marked out of 1.00
Flag question
Question text
Given the following:

class ShapeException extends Exception {

}



class CircleException extends ShapeException {

}



public class Circle2 {

 void m1() throws ShapeException {

  throw new CircleException();

 }



 public static void main(String[] args) {

  Circle2 circle2 = new Circle2();

  int a = 0, b = 0;



  try {

   circle2.m1();

   a++;

  } catch (ShapeException e) {

   b++;

  }



  System.out.printf("a=%d, b=%d", a, b);

 }

}

What is the expected output ?



Question 3Answer

a.
a=0, b=0 


b.
a=1, b=0 


c.
a=0, b=1


d.
Compile time error at line 6. 

Question 4
Complete
Marked out of 1.00
Flag question
Question text
Given the following program, which one of the statements is true?

public class Exceptions {

    public static void main(String[] args) {

        try {

            if (args.length == 0) return;

            System.out.println(args[0]);

        } finally {

            System.out.println("The end");

        }

    }

}



Question 4Answer

a.
If run with one argument, the program will simply print the given argument. 


b.
The program will throw an ArrayIndexOutOfBoundsException. 


c.
If run with one argument, the program will produce no output. 


d.
If run with one argument, the program will print the given argument followed by "The end".

Question 5
Complete
Marked out of 1.00
Flag question
Question text
Given:

public class TestException {

 public static void main(String... args) {

  try {

   // some piece of code

  } catch (NullPointerException e1) {

   System.out.print("n");

  } catch (RuntimeException e2) {

   System.out.print("r");

  } finally {

   System.out.print("f");

  }

 }

}

What is the output if NullPointerException occurs when executing the code in the try block?



Question 5Answer

a.
nf


b.
f


c.
nrf


d.
rf

Question 6
Complete
Marked out of 1.00
Flag question
Question text
On occurrence of which of the following is it possible for a program to recover?

Question 6Answer

a.
Errors 


b.
Neither 


c.
Exceptions


d.
Both errors and exceptions 

Question 7
Complete
Marked out of 1.00
Flag question
Question text
Which statement is TRUE about the try{} block?

Question 7Answer

a.
The statements in a try{} block can only throw one exception type and not several types. 


b.
It is mandatory for statements in a try{} block to throw at least one exception type. 


c.
The try{} block can contain loops or branches.


d.
The try{} block can appear after the catch{} blocks. 

Question 8
Complete
Marked out of 1.00
Flag question
Question text
Which of these statement is true ?

Question 8Answer

a.
finally block can be present only when a catch block is present. 


b.
Finally gets always executed irrespective of the flow in try catch block.


c.
finally block gets executed only when there are no exceptions. 


d.
finally block gets executed only when there are exceptions. 

Question 9
Complete
Marked out of 1.00
Flag question
Question text
If a try statement has catch blocks for both Exception and IOException, then which of the following statements is correct?

Question 9Answer

a.
The catch block for Exception must appear before the catch block for IOException.


b.
A try statement cannot be declared with these two catch block types because they are incompatible.


c.
The catch block for IOException must appear before the catch block for Exception.


d.
The catch blocks for these two exception types can be declared in any order.

Question 10
Complete
Marked out of 1.00
Flag question
Question text
Given the following:

public class TestIfBoolean {

 public static void main(String[] args) {

  Boolean bFlag = null;

  if (bFlag) {

   System.out.print("A");

  } else if (bFlag == false) {

   System.out.print("B");

  } else {

   System.out.print("C");

  }

 }

}

What is the expected output?



Question 10Answer

a.
C


b.
A


c.
B


d.
java.lang.NullPointerException is thrown at runtime

Question 11
Complete
Marked out of 1.00
Flag question
Question text
Given the following code in the 3 java files:

NewException.java

class NewException extends Exception {

}

Welcome.java

class Welcome {

public String displayWelcome(String name) throws NewException {

if(name == null) {

throw new NewException();

}

return "Welcome "+ name;

}

}

TestNewException.java

class TestNewException {

public static void main(String... args) {

Welcome w = new Welcome();

System.out.println(w.displayWelcome("Ram"));

}

}

What is the result on compiling and executing it ?



Question 11Answer

a.
Compilation of TestNewException.java fails


b.
Runtime exception occurs on executing the class TestNewException. 


c.
Compiles successfully and displays Ram when TestNewException is executed. 


d.
Compilation of Welcome.java fails. 

Question 12
Complete
Marked out of 1.00
Flag question
Question text
Which of the following lists exception types from MOST specific to LEAST specific?

Question 12Answer

a.
Error, Exception 


b.
Throwable, RunTimeException 


c.
Exception, RunTimeException 


d.
ArithmeticException, RunTimeException

Question 13
Complete
Marked out of 1.00
Flag question
Question text
Given the following,

1. import java.io.*;

2. public class MyProgram {

3. public static void main(String args[]){

4. FileOutputStream out = null;

5. try {

6. out = new FileOutputStream("test.txt");

7. out.write(122);

8. }

9. catch(IOException io) {

10. System.out.println("IO Error.");

11. }

12. finally {

13. out.close();unhandled exception

14. }

15. }

16. }

and given that all methods of class FileOutputStream, including close(), throw an IOException, which one of these is true?



Question 13Answer

a.
This program will compile successfully. 


b.
This program fails to compile due to an error at line 13.


c.
This program fails to compile due to an error at line 9. 


d.
This program fails to compile due to an error at line 6. 

Question 14
Complete
Marked out of 1.00
Flag question
Question text
Given the following code:

public class ArithmeticTest {

    public static void main(String[] args){

        try

        {

            int x=0;

            int y=5/x;

            System.out.printlnYes;

        }

        catch (Exception e)

        {

            System.out.println("Exception");

        }

        catch (ArithmeticException ae)

        {

            System.out.println("ArithmeticException");

        }

    }

}

What is the output?



Question 14Answer

a.
Compilation Error


b.
NaN 


c.
Exception 


d.
ArithmeticException 

Question 15
Complete
Marked out of 1.00
Flag question
Question text
What is the result of compiling and executing the below code ?

public class TryTest {

    public static void main(String[] args)

    {

        try

        {

            return;

        }

        finally

        {

            System.out.println("Finally");

        }

    }

}



Question 15Answer

a.
Outputs nothing 


b.
Finally


c.
Runtime Error 


d.
Compilation Error 

Question 16
Complete
Marked out of 1.00
Flag question
Question text
Both class Error and class Exception are children of this parent:

Question 16Answer

a.
Runnable 


b.
Throwable


c.
Problem 


d.
Catchable 

Question 17
Complete
Marked out of 1.00
Flag question
Question text
class A {A() throws Exception {}} // 1

class B extends A {B() throws Exception {}} // 2

class C extends A {C() {}} // 3

Which one of the following statements is true?



Question 17Answer

a.
Compile-time error at 2. 


b.
Compile-time error at 3.


c.
No compile-time errors. 


d.
Compile-time error at 1. 

Question 18
Complete
Marked out of 1.00
Flag question
Question text
When is a finally{} block executed?

Question 18Answer

a.
Always just as a method is about to finish. 


b.
Only when any exception is thrown in a try{} block. 


c.
Only when an unhandled exception is thrown in a try{} block. 


d.
Always after execution has left a try catch{} block, no matter for what reason

Question 19
Complete
Marked out of 1.00
Flag question
Question text
Given:

1.  public class B {

2.     Integer x;

3.     int sum;

4.     public B(int y) {

5.         sum=x+y;

6.         System.out.println(sum);

7.     }

8.     public static void main(String[] args) {

9.         new B(new Integer(23));

10.    }

11. }

What is the expected output?



Question 19Answer

a.
The value "23" is printed at the command line. 


b.
A NullPointerException occurs at runtime.


c.
Compilation fails because of an error in line 9. 


d.
A NumberFormatException occurs at runtime. 

Question 20
Complete
Marked out of 1.00
Flag question
Question text
class A {

    public static void main (String[] args) {

        Error error = new Error();

        Exception exception = new Exception();

        System.out.print((exception instanceof Throwable) + ",");

        System.out.print(error instanceof Throwable);

}}

What is the result of attempting to compile and run the program?



Question 20Answer

a.
Prints: false,false 


b.
Prints: false,true 


c.
Prints: true,true


d.
Prints: true,false 

Question 21
Complete
Marked out of 1.00
Flag question
Question text
Given the following:

1. class ShapeException extends Exception {}

2.

3. class CircleException extends ShapeException {}

4. 

5. public class Circle1 {

6.     void m1() throws CircleException {throw new ShapeException();}

7.     

8.     public static void main (String[] args) {

9.         Circle1 circle1 = new Circle1();

10.        int a=1, b=1;

11.        

12.        try {circle1.m1(); a--;} catch (CircleException e) {b--;}

13.        

14.        System.out.printf("a=%d, b=%d", a, b);

15.    }

16.}

What is the expected output?



Question 21Answer

a.
a=0, b=1 


b.
Compile time error at line 6.


c.
a=1, b=1 


d.
a=1, b=0 

Question 22
Complete
Marked out of 1.00
Flag question
Question text
What is the output of following code?

class Main {

   public static void main(String args[]) {

      int x = 0;

      int y = 10;

      int z = y/x;

  }

}

Question 22Answer

a.
Complies and runs fine


b.
Complier Error


c.
Compiles fine but throws ArithmeticException


d.
None of the mentioned

Question 23
Complete
Marked out of 1.00
Flag question
Question text
What type of exception is thrown by parseInt() if it gets illegal data?

Question 23Answer

a.
RunTimeException 


b.
ArithmeticException 


c.
NumberError 


d.
NumberFormatException

Question 24
Complete
Marked out of 1.00
Flag question
Question text
Which statement is true?

Question 24Answer

a.
A method declaring that it throws a certain exception class may throw instances of any subclass of that exception class.


b.
If an exception is uncaught in a method, the method will terminate and normal execution will resume. 


c.
An overriding method must declare that it throws the same exception classes as the method it overrides. 


d.
The main() method of a program cannot declare that it throws checked exceptions. 

Question 25
Complete
Marked out of 1.00
Flag question
Question text
Given the following:

public class TestDivide {

    public static void main(String[] args) {

        int value=0;

        try {

            int result = 10/value;

        } finally {

            System.out.println("f");

        }

    }

}

What is the result ?



Question 25Answer

a.
Compilation fails since a catch block is not present. 


b.
Prints only "f" in the output. 


c.
Prints an "f" in the output and a runtime error is also displayed.


d.
Only a runtime error is displayed. 

Question 26
Complete
Marked out of 1.00
Flag question
Question text
class A {

    public static void main (String[] args) {

        Object error = new Error();

        Object runtimeException = new RuntimeException();

        System.out.print((error instanceof Exception) + ",");

        System.out.print(runtimeException instanceof Exception);

}}

What is the result of attempting to compile and run the program?



Question 26Answer

a.
Prints: true,false 


b.
Prints: false,false 


c.
Prints: false,true


d.
Prints: true,true 

Question 27
Complete
Marked out of 1.00
Flag question
Question text
public class ExceptionTest {

    public static void main(String[] args)

    {

        try

        {

            ExceptionTest a = new ExceptionTest();

            a.badMethod();

            System.out.println("A");

        }

        catch (Exception e)

        {

            System.out.println("B");

        }

        finally

        {

            System.out.println("C");

        }

    }



    void badMethod()

    {

        throw new Error();

    }

}

What is the output?



Question 27Answer

a.
Error exception followed by C 


b.
C followed by Error exception


c.
Error exception followed by BC 


d.
BC followed by Error exception

Question 28
Complete
Marked out of 1.00
Flag question
Question text
public class MyClass {

    public static void main(String[] args) {

        RuntimeException re = null;

        throw re;

    }

}

What will be the result of attempting to compile and run the above program?



Question 28Answer

a.
The program will compile without error and will throw java.lang.NullpointerException when run.


b.
The program will compile without error and will throw java.lang.RuntimeException when run. 


c.
The code will fail to compile, since the main() method does not declare that it throws RuntimeException in its declaration.


d.
The program will compile without error and will run and terminate without any output. 

Question 29
Complete
Marked out of 1.00
Flag question
Question text
Which statement is TRUE about catch{} blocks?

Question 29Answer

a.
There can only be one catch{} block in a try/catch structure. 


b.
A catch{} block need not be present even if there is no finally{} block. 


c.
The catch{} block for a child exception class must PRECEDE that of a parent exception class.


d.
The catch{} block for a child exception class must FOLLOW that of a parent exception class. 

Question 30
Complete
Marked out of 1.00
Flag question
Question text
Given the following:

1. System.out.print("Start ");

2. try {

3.     System.out.print("Hello world");

4.     throw new FileNotFoundException();

5. }

6. System.out.print(" Catch Here ");

7. catch(EOFException e) {

8.     System.out.print("End of file exception");

9. }

10. catch(FileNotFoundException e) {

11.     System.out.print("File not found");

12. }

and given that EOFException and FileNotFoundException are both subclasses of IOException, and further assuming this block of code is placed into a class, which statement is most true concerning this code?



Question 30Answer

a.
Code output: Start Hello world Catch Here File not found.


b.
Code output: Start Hello world End of file exception. 


c.
Code output: Start Hello world File Not Found. 


d.
The code will not compile.

Question 31
Complete
Marked out of 1.00
Flag question
Question text
Given the following code:

import java.io.IOException;



public class ExceptionTest {

 public static void main(String[] args) {

  try {

   methodA();

  } catch (IOException e) {

   System.out.println("Caught IO Exception");

  } catch (Exception e) {

   System.out.println("Caught Exception");

  }

 }



 static public void methodA() {

  throw new IOException();

 }

}

What is the output ?



Question 31Answer

a.
The output is "Caught Exception". 


b.
Code will not compile.


c.
The output is "Caught IO Exception". 


d.
Program executes normally without printing a message. 

Question 32
Complete
Marked out of 1.00
Flag question
Question text
Given the following:

1. class Base {

2. void display() throws Exception { throw new Exception(); }

3. }

4. public class Derived extends Base {

5. void display() { System.out.println("Derived"); }

6. public static void main(String[] args) {

7. new Derived().display();

8. }

9. }

What is the result ?



Question 32Answer

a.
Compilation fails because of an error in line 2. 


b.
Derived


c.
Compilation fails because of an error in line 7. 


d.
The code runs with no output. 

Question 33
Complete
Marked out of 1.00
Flag question
Question text
Given the following,

1. public class MyProgram {

2.     public static void main(String args[]){

3.         try {

4.             System.out.print("Hello world ");

5.         }

6.         finally {

7.             System.out.println("Finally executing ");

8.         }

9.     }

10. }

What is the result?



Question 33Answer

a.
Nothing. The program will not compile because no catch clauses are specified. 


b.
Hello world. 


c.
Nothing. The program will not compile because no exceptions are specified. 


d.
Hello world Finally executing

Question 34
Complete
Marked out of 1.00
Flag question
Question text
What is the output of following code

class Main {

   public static void main(String args[]) {

      try {

         throw 10;

      }

      catch(int e) {

         System.out.println("Got the  Exception " + e);

      }

  }

}

Question 34Answer

a.
Got the exception 0


b.
Got the exception 10


c.
Runtime error


d.
Compiler Error

Question 35
Complete
Marked out of 1.00
Flag question
Question text
Given the following,

1. public class RTExcept {

2. public static void throwit () {

3. System.out.print("throwit ");

4. throw new RuntimeException();

5. }

6. public static void main(String [] args) {

7. try {

8. System.out.print("hello ");

9. throwit();

10. }

11. catch (Exception re ) {

12. System.out.print("caught ");

13. }

14. finally {

15. System.out.print("finally ");

16. }

17. System.out.println("after ");

18. }

19. }

What is the output ?



Question 35Answer

a.
hello throwit RuntimeException caught after 


b.
hello throwit caught finally after RuntimeException 


c.
hello throwit caught finally after


d.
hello throwit caught 
